  <?xml version="1.0" ?>
  <sdf version="1.6">
    <model name="prototype">



      <link name="base_link">
        <inertial>
          <pose>0.0 0.0 -0.05 0 0 0</pose>
          <mass>1.0</mass>
          <inertia>
            <ixx>0.201</ixx>
            <ixy>0</ixy>
            <ixz>0</ixz>
            <iyy>0.223</iyy>
            <iyz>0</iyz>
            <izz>0.269</izz>
          </inertia>
        </inertial>
        <visual name="base_link_visual">
          <geometry>
            <mesh>
              <uri>model://prototype_vehicle/meshes/sim.obj</uri>
              <scale>1 1 1</scale>
            </mesh>
          </geometry>
        </visual>
        <collision name="base_link_collision">
          <geometry>
            <mesh>
              <uri>model://prototype_vehicle/meshes/sim.obj</uri>
              <scale>1 1 1</scale>
            </mesh>
          </geometry>
        </collision>




      <sensor name="imu_sensor" type="imu">
        <!-- Transform from the Gazebo body frame (x-forward, y-left, z-up)
             to the ArduPilot body frame (x-forward, y-right, z-down) -->
        <pose>0 0 0 3.142 0 0</pose>
        <always_on>1</always_on>
        <update_rate>400.0</update_rate>
      </sensor>

      <sensor name="vio_imu" type="imu">
        <!-- vio IMU -->
        <pose>0 0 0 0 0 0</pose>
        <always_on>1</always_on>
        <update_rate>300.0</update_rate>
        <topic>/imu0</topic>
      </sensor>
      </link>

    <plugin
        filename="gz-sim-hydrodynamics-system"
        name="gz::sim::systems::Hydrodynamics">
      <link_name>base_link</link_name>
      <water_density>1000.0</water_density>
      <!-- Added mass: -->
      <xDotU>0</xDotU>
      <yDotV>0</yDotV>
      <zDotW>0</zDotW>
      <kDotP>0</kDotP>
      <mDotQ>0</mDotQ>
      <nDotR>0</nDotR>
      <!-- First order stability derivative: -->
      <xU>0</xU>
      <yV>0</yV>
      <zW>0</zW>
      <kP>0</kP>
      <mQ>0</mQ>
      <nR>0</nR>
      <!-- Second order stability derivative: -->
      <xUabsU>-58.42</xUabsU>
      <yVabsV>-55.137</yVabsV>
      <zWabsW>-124.818</zWabsW>
      <kPabsP>-4.0</kPabsP>
      <mQabsQ>-4.0</mQabsQ>
      <nRabsR>-4.0</nRabsR>
    </plugin>




    <link name="thruster1">
      <pose>0.220155 -0.112663 -0.022411 -1.571 1.571 -0.785</pose>
      <visual name="thruster_prop_visual">
        <pose>0 0 0 -1.571 0 0</pose>
        <geometry>
          <mesh>
            <uri>model://bluerov2_heavy/meshes/t200_ccw_prop.dae</uri>
          </mesh>
        </geometry>
        <cast_shadows>false</cast_shadows>
      </visual>
      <inertial>
        <mass>0.002</mass>
        <inertia>
          <ixx>0.001</ixx>
          <ixy>0</ixy>
          <ixz>0</ixz>
          <iyy>0.001</iyy>
          <iyz>0</iyz>
          <izz>0.001</izz>
        </inertia>
      </inertial>
    </link>


    <link name="thruster2">
      <pose>0.220155 0.112663 -0.022411 -1.571 1.571 -2.356</pose>
      <visual name="thruster_prop_visual">
        <pose>0 0 0 -1.571 0 0</pose>
        <geometry>
          <mesh>
            <uri>model://bluerov2_heavy/meshes/t200_ccw_prop.dae</uri>
          </mesh>
        </geometry>
        <cast_shadows>false</cast_shadows>
      </visual>
      <inertial>
        <mass>0.002</mass>
        <inertia>
          <ixx>0.001</ixx>
          <ixy>0</ixy>
          <ixz>0</ixz>
          <iyy>0.001</iyy>
          <iyz>0</iyz>
          <izz>0.001</izz>
        </inertia>
      </inertial>
    </link>


    <link name="thruster3">
      <pose>-0.220155 -0.112663 -0.022411 -1.571 1.571 0.785</pose>
      <visual name="thruster_prop_visual">
        <pose>0 0 0 1.571 0 0</pose>
        <geometry>
          <mesh>
            <uri>model://bluerov2_heavy/meshes/t200_cw_prop.dae</uri>
          </mesh>
        </geometry>
        <cast_shadows>false</cast_shadows>
      </visual>
      <inertial>
        <mass>0.002</mass>
        <inertia>
          <ixx>0.001</ixx>
          <ixy>0</ixy>
          <ixz>0</ixz>
          <iyy>0.001</iyy>
          <iyz>0</iyz>
          <izz>0.001</izz>
        </inertia>
      </inertial>
    </link>


        <link name="thruster4">
      <pose>-0.220155 0.112663 -0.022411 -1.571 1.571 0.785</pose>
      <visual name="thruster_prop_visual">
        <pose>0 0 0 1.571 0 0</pose>
        <geometry>
          <mesh>
            <uri>model://bluerov2_heavy/meshes/t200_cw_prop.dae</uri>
          </mesh>
        </geometry>
        <cast_shadows>false</cast_shadows>
      </visual>
      <inertial>
        <mass>0.002</mass>
        <inertia>
          <ixx>0.001</ixx>
          <ixy>0</ixy>
          <ixz>0</ixz>
          <iyy>0.001</iyy>
          <iyz>0</iyz>
          <izz>0.001</izz>
        </inertia>
      </inertial>
    </link>


    <link name="thruster5">
      <pose>0.088444 -0.212676 0.005653 0 0 0</pose>
      <visual name="thruster_prop_visual">
        <pose>0 0 0 -1.571 0 1.571</pose>
        <geometry>
          <mesh>
            <uri>model://bluerov2_heavy/meshes/t200_ccw_prop.dae</uri>
          </mesh>
        </geometry>
        <cast_shadows>false</cast_shadows>
      </visual>
      <inertial>
        <mass>0.002</mass>
        <inertia>
          <ixx>0.001</ixx>
          <ixy>0</ixy>
          <ixz>0</ixz>
          <iyy>0.001</iyy>
          <iyz>0</iyz>
          <izz>0.001</izz>
        </inertia>
      </inertial>
    </link>

    <link name="thruster6">
      <pose>0.088444 0.212676 0.005653 0 0 0</pose>
      <visual name="thruster_prop_visual">
        <pose>0 0 0 1.571 0 1.571</pose>
        <geometry>
          <mesh>
            <uri>model://bluerov2_heavy/meshes/t200_cw_prop.dae</uri>
          </mesh>
        </geometry>
        <cast_shadows>false</cast_shadows>
      </visual>
      <inertial>
        <mass>0.002</mass>
        <inertia>
          <ixx>0.001</ixx>
          <ixy>0</ixy>
          <ixz>0</ixz>
          <iyy>0.001</iyy>
          <iyz>0</iyz>
          <izz>0.001</izz>
        </inertia>
      </inertial>
    </link>


    <link name="thruster7">
      <pose>-0.088444 -0.212676 0.005653 0 0 0</pose>
      <visual name="thruster_prop_visual">
        <pose>0 0 0 1.571 0 1.571</pose>
        <geometry>
          <mesh>
            <uri>model://bluerov2_heavy/meshes/t200_cw_prop.dae</uri>
          </mesh>
        </geometry>
        <cast_shadows>false</cast_shadows>
      </visual>
      <inertial>
        <mass>0.002</mass>
        <inertia>
          <ixx>0.001</ixx>
          <ixy>0</ixy>
          <ixz>0</ixz>
          <iyy>0.001</iyy>
          <iyz>0</iyz>
          <izz>0.001</izz>
        </inertia>
      </inertial>
    </link>

    <link name="thruster8">
      <pose>-0.088444 0.212676 0.005653 0 0 0</pose>
      <visual name="thruster_prop_visual">
        <pose>0 0 0 -1.571 0 1.571</pose>
        <geometry>
          <mesh>
            <uri>model://bluerov2_heavy/meshes/t200_ccw_prop.dae</uri>
          </mesh>
        </geometry>
        <cast_shadows>false</cast_shadows>
      </visual>
      <inertial>
        <mass>0.002</mass>
        <inertia>
          <ixx>0.001</ixx>
          <ixy>0</ixy>
          <ixz>0</ixz>
          <iyy>0.001</iyy>
          <iyz>0</iyz>
          <izz>0.001</izz>
        </inertia>
      </inertial>
    </link>


    <joint name="thruster1_joint" type="revolute">
      <parent>base_link</parent>
      <child>thruster1</child>
      <axis>
        <xyz>0 0 -1</xyz>
      </axis>
    </joint>

    <joint name="thruster2_joint" type="revolute">
      <parent>base_link</parent>
      <child>thruster2</child>
      <axis>
        <xyz>0 0 -1</xyz>
      </axis>
    </joint>

    <joint name="thruster3_joint" type="revolute">
      <parent>base_link</parent>
      <child>thruster3</child>
      <axis>
        <xyz>0 0 -1</xyz>
      </axis>
    </joint>

    <joint name="thruster4_joint" type="revolute">
      <parent>base_link</parent>
      <child>thruster4</child>
      <axis>
        <xyz>0 0 -1</xyz>
      </axis>
    </joint>

    <joint name="thruster5_joint" type="revolute">
      <parent>base_link</parent>
      <child>thruster5</child>
      <axis>
        <xyz>0 0 -1</xyz>
      </axis>
    </joint>

    <joint name="thruster6_joint" type="revolute">
      <parent>base_link</parent>
      <child>thruster6</child>
      <axis>
        <xyz>0 0 -1</xyz>
      </axis>
    </joint>

    <joint name="thruster7_joint" type="revolute">
      <parent>base_link</parent>
      <child>thruster7</child>
      <axis>
        <xyz>0 0 -1</xyz>
      </axis>
    </joint>

    <joint name="thruster8_joint" type="revolute">
      <parent>base_link</parent>
      <child>thruster8</child>
      <axis>
        <xyz>0 0 -1</xyz>
      </axis>
    </joint>


    <plugin
        filename="gz-sim-thruster-system"
        name="gz::sim::systems::Thruster">
      <namespace>prototype</namespace>
      <joint_name>thruster1_joint</joint_name>
      <thrust_coefficient>0.02</thrust_coefficient>
      <fluid_density>1000.0</fluid_density>
      <propeller_diameter>0.1</propeller_diameter>
      <velocity_control>true</velocity_control>
      <use_angvel_cmd>False</use_angvel_cmd>
    </plugin>

    <plugin
        filename="gz-sim-thruster-system"
        name="gz::sim::systems::Thruster">
      <namespace>prototype</namespace>
      <joint_name>thruster2_joint</joint_name>
      <thrust_coefficient>0.02</thrust_coefficient>
      <fluid_density>1000.0</fluid_density>
      <propeller_diameter>0.1</propeller_diameter>
      <velocity_control>true</velocity_control>
      <use_angvel_cmd>False</use_angvel_cmd>
    </plugin>

    <plugin
        filename="gz-sim-thruster-system"
        name="gz::sim::systems::Thruster">
      <namespace>prototype</namespace>
      <joint_name>thruster3_joint</joint_name>
      <!-- Reverse spin to balance torque -->
      <thrust_coefficient>-0.02</thrust_coefficient>
      <fluid_density>1000.0</fluid_density>
      <propeller_diameter>0.1</propeller_diameter>
      <velocity_control>true</velocity_control>
      <use_angvel_cmd>False</use_angvel_cmd>
    </plugin>

    <plugin
        filename="gz-sim-thruster-system"
        name="gz::sim::systems::Thruster">
      <namespace>prototype</namespace>
      <joint_name>thruster4_joint</joint_name>
      <!-- Reverse spin to balance torque -->
      <thrust_coefficient>-0.02</thrust_coefficient>
      <fluid_density>1000.0</fluid_density>
      <propeller_diameter>0.1</propeller_diameter>
      <velocity_control>true</velocity_control>
      <use_angvel_cmd>False</use_angvel_cmd>
    </plugin>

    <plugin
        filename="gz-sim-thruster-system"
        name="gz::sim::systems::Thruster">
      <namespace>prototype</namespace>
      <joint_name>thruster5_joint</joint_name>
      <thrust_coefficient>0.02</thrust_coefficient>
      <fluid_density>1000.0</fluid_density>
      <propeller_diameter>0.1</propeller_diameter>
      <velocity_control>true</velocity_control>
      <use_angvel_cmd>False</use_angvel_cmd>
    </plugin>

    <plugin
        filename="gz-sim-thruster-system"
        name="gz::sim::systems::Thruster">
      <namespace>prototype</namespace>
      <joint_name>thruster6_joint</joint_name>
      <!-- Reverse spin to balance torque -->
      <thrust_coefficient>-0.02</thrust_coefficient>
      <fluid_density>1000.0</fluid_density>
      <propeller_diameter>0.1</propeller_diameter>
      <velocity_control>true</velocity_control>
      <use_angvel_cmd>False</use_angvel_cmd>
    </plugin>

    <plugin
        filename="gz-sim-thruster-system"
        name="gz::sim::systems::Thruster">
      <namespace>prototype</namespace>
      <joint_name>thruster7_joint</joint_name>
      <!-- Reverse spin to balance torque -->
      <thrust_coefficient>-0.02</thrust_coefficient>
      <fluid_density>1000.0</fluid_density>
      <propeller_diameter>0.1</propeller_diameter>
      <velocity_control>true</velocity_control>
      <use_angvel_cmd>False</use_angvel_cmd>
    </plugin>

    <plugin
        filename="gz-sim-thruster-system"
        name="gz::sim::systems::Thruster">
      <namespace>prototype</namespace>
      <joint_name>thruster8_joint</joint_name>
      <thrust_coefficient>0.02</thrust_coefficient>
      <fluid_density>1000.0</fluid_density>
      <propeller_diameter>0.1</propeller_diameter>
      <velocity_control>true</velocity_control>
      <use_angvel_cmd>False</use_angvel_cmd>
    </plugin>


    <plugin name="ArduPilotPlugin" filename="libArduPilotPlugin.so">
      <!-- Port settings -->
      <fdm_addr>127.0.0.1</fdm_addr>
      <fdm_port_in>9002</fdm_port_in>
      <connectionTimeoutMaxCount>5</connectionTimeoutMaxCount>
      <lock_step>1</lock_step>

      <!-- Transform from the Gazebo body frame (x-forward, y-left, z-up)
           to the ArduPilot body frame (x-forward, y-right, z-down) -->
      <modelXYZToAirplaneXForwardZDown>0 0 0 3.142 0 0</modelXYZToAirplaneXForwardZDown>

      <!-- Transform from the Gazebo world frame (ENU)
           to the ArduPilot world frame (NED) -->
      <gazeboXYZToNED>0 0 0 3.142 0 1.571</gazeboXYZToNED>

      <!-- Sensors -->
      <imuName>imu_sensor</imuName>

      <!-- Thrusters -->
      <control channel="0">
        <jointName>thruster1_joint</jointName>
        <servo_min>1000</servo_min>
        <servo_max>2000</servo_max>
        <type>COMMAND</type>
        <cmd_topic>/model/prototype/joint/thruster1_joint/cmd_thrust</cmd_topic>
        <offset>-0.5</offset>
        <multiplier>100</multiplier>
      </control>
      <control channel="1">
        <jointName>thruster2_joint</jointName>
        <servo_min>1100</servo_min>
        <servo_max>1900</servo_max>
        <type>COMMAND</type>
        <cmd_topic>/model/prototype/joint/thruster2_joint/cmd_thrust</cmd_topic>
        <offset>-0.5</offset>
        <multiplier>100</multiplier>
      </control>
      <control channel="2">
        <jointName>thruster3_joint</jointName>
        <servo_min>1100</servo_min>
        <servo_max>1900</servo_max>
        <type>COMMAND</type>
        <cmd_topic>/model/prototype/joint/thruster3_joint/cmd_thrust</cmd_topic>
        <offset>-0.5</offset>
        <multiplier>100</multiplier>
      </control>
      <control channel="3">
        <jointName>thruster4_joint</jointName>
        <servo_min>1100</servo_min>
        <servo_max>1900</servo_max>
        <type>COMMAND</type>
        <cmd_topic>/model/prototype/joint/thruster4_joint/cmd_thrust</cmd_topic>
        <offset>-0.5</offset>
        <multiplier>100</multiplier>
      </control>
      <control channel="4">
        <jointName>thruster5_joint</jointName>
        <servo_min>1100</servo_min>
        <servo_max>1900</servo_max>
        <type>COMMAND</type>
        <cmd_topic>/model/prototype/joint/thruster5_joint/cmd_thrust</cmd_topic>
        <offset>-0.5</offset>
        <multiplier>100</multiplier>
      </control>
      <control channel="5">bluerov2_heavy
        <jointName>thruster6_joint</jointName>
        <servo_min>1100</servo_min>
        <servo_max>1900</servo_max>
        <type>COMMAND</type>
        <cmd_topic>/model/prototype/joint/thruster6_joint/cmd_thrust</cmd_topic>
        <offset>-0.5</offset>
        <multiplier>100</multiplier>
      </control>
      <control channel="6">
        <jointName>thruster7_joint</jointName>
        <servo_min>1100</servo_min>
        <servo_max>1900</servo_max>bluerov2_heavy
        <type>COMMAND</type>
        <cmd_topic>/model/prototype/joint/thruster7_joint/cmd_thrust</cmd_topic>
        <offset>-0.5</offset>
        <multiplier>100</multiplier>
      </control>
      <control channel="7">
        <jointName>thruster8_joint</jointName>
        <servo_min>1100</servo_min>
        <servo_max>1900</servo_max>
        <type>COMMAND</type>
        <cmd_topic>/model/prototype/joint/thruster8_joint/cmd_thrust</cmd_topic>
        <offset>-0.5</offset>
        <multiplier>100</multiplier>
      </control>

    </plugin>



    </model>
  </sdf>