<?xml version="1.0" ?>
<!-- =================================================================================== -->
<!-- |    This document was autogenerated by xacro from prototype.urdf.xacro           | -->
<!-- |    EDITING THIS FILE BY HAND IS NOT RECOMMENDED                                 | -->
<!-- =================================================================================== -->
<robot name="prototype">
  <gazebo>
    <plugin filename="gz-sim-hydrodynamics-system" name="gz::sim::systems::Hydrodynamics">
      <link_name>base_link</link_name>
      <water_density>1000.0</water_density>
      <xDotU>0</xDotU>
      <yDotV>0</yDotV>
      <zDotW>0</zDotW>
      <kDotP>0</kDotP>
      <mDotQ>0</mDotQ>
      <nDotR>0</nDotR>
      <xU>0</xU>
      <yV>0</yV>
      <zW>0</zW>
      <kP>0</kP>
      <mQ>0</mQ>
      <nR>0</nR>
      <xUabsU>-58.42</xUabsU>
      <yVabsV>-55.137</yVabsV>
      <zWabsW>-124.818</zWabsW>
      <kPabsP>-4.0</kPabsP>
      <mQabsQ>-4.0</mQabsQ>
      <nRabsR>-4.0</nRabsR>
    </plugin>
    <plugin filename="libArduPilotPlugin.so" name="ArduPilotPlugin">
      <fdm_addr>127.0.0.1</fdm_addr>
      <fdm_port_in>9002</fdm_port_in>
      <connectionTimeoutMaxCount>5</connectionTimeoutMaxCount>
      <lock_step>1</lock_step>
      <modelXYZToAirplaneXForwardZDown>0 0 0 3.142 0 0</modelXYZToAirplaneXForwardZDown>
      <gazeboXYZToNED>0 0 0 3.142 0 1.571</gazeboXYZToNED>
      <imuName>imu_sensor</imuName>
      <control channel="0">
        <jointName>thruster1_joint</jointName>
        <servo_min>1000</servo_min>
        <servo_max>2000</servo_max>
        <type>COMMAND</type>
        <cmd_topic>/model/prototype/joint/thruster1_joint/cmd_thrust</cmd_topic>
        <offset>-0.5</offset>
        <multiplier>100</multiplier>
      </control>
      <control channel="1">
        <jointName>thruster2_joint</jointName>
        <servo_min>1100</servo_min>
        <servo_max>1900</servo_max>
        <type>COMMAND</type>
        <cmd_topic>/model/prototype/joint/thruster2_joint/cmd_thrust</cmd_topic>
        <offset>-0.5</offset>
        <multiplier>100</multiplier>
      </control>
      <control channel="2">
        <jointName>thruster3_joint</jointName>
        <servo_min>1100</servo_min>
        <servo_max>1900</servo_max>
        <type>COMMAND</type>
        <cmd_topic>/model/prototype/joint/thruster3_joint/cmd_thrust</cmd_topic>
        <offset>-0.5</offset>
        <multiplier>100</multiplier>
      </control>
      <control channel="3">
        <jointName>thruster4_joint</jointName>
        <servo_min>1100</servo_min>
        <servo_max>1900</servo_max>
        <type>COMMAND</type>
        <cmd_topic>/model/prototype/joint/thruster4_joint/cmd_thrust</cmd_topic>
        <offset>-0.5</offset>
        <multiplier>100</multiplier>
      </control>
      <control channel="4">
        <jointName>thruster5_joint</jointName>
        <servo_min>1100</servo_min>
        <servo_max>1900</servo_max>
        <type>COMMAND</type>
        <cmd_topic>/model/prototype/joint/thruster5_joint/cmd_thrust</cmd_topic>
        <offset>-0.5</offset>
        <multiplier>100</multiplier>
      </control>
      <control channel="5">
        <jointName>thruster6_joint</jointName>
        <servo_min>1100</servo_min>
        <servo_max>1900</servo_max>
        <type>COMMAND</type>
        <cmd_topic>/model/prototype/joint/thruster6_joint/cmd_thrust</cmd_topic>
        <offset>-0.5</offset>
        <multiplier>100</multiplier>
      </control>
      <control channel="6">
        <jointName>thruster7_joint</jointName>
        <servo_min>1100</servo_min>
        <servo_max>1900</servo_max>
        <type>COMMAND</type>
        <cmd_topic>/model/prototype/joint/thruster7_joint/cmd_thrust</cmd_topic>
        <offset>-0.5</offset>
        <multiplier>100</multiplier>
      </control>
      <control channel="7">
        <jointName>thruster8_joint</jointName>
        <servo_min>1100</servo_min>
        <servo_max>1900</servo_max>
        <type>COMMAND</type>
        <cmd_topic>/model/prototype/joint/thruster8_joint/cmd_thrust</cmd_topic>
        <offset>-0.5</offset>
        <multiplier>100</multiplier>
      </control>
    </plugin>
  </gazebo>
  <link name="base_link">
    <inertial>
      <origin rpy="0 0 0" xyz="0 0 -0.05"/>
      <mass value="11.0"/>
      <inertia ixx="0.201" ixy="0" ixz="0" iyy="0.223" iyz="0" izz="0.269"/>
    </inertial>
    <visual>
      <geometry>
        <mesh filename="model://prototype_vehicle/meshes/sim.obj"/>
      </geometry>
    </visual>
    <visual name="left_top_pipe_visual">
      <origin rpy="0 1.5707963267948966 0" xyz="0.001 0.156 0.1417"/>
      <geometry>
        <cylinder length="0.365" radius="0.0125"/>
      </geometry>
      <material name="dark_gray">
        <color rgba="0.1 0.1 0.1 1"/>
      </material>
    </visual>
    <collision name="left_top_pipe_collision">
      <origin rpy="0 1.5707963267948966 0" xyz="0.001 0.156 0.1417"/>
      <geometry>
        <cylinder length="0.365" radius="0.0125"/>
      </geometry>
    </collision>
    <visual name="right_top_pipe_visual">
      <origin rpy="0 1.5707963267948966 0" xyz="0.001 -0.156 0.1417"/>
      <geometry>
        <cylinder length="0.365" radius="0.0125"/>
      </geometry>
      <material name="dark_gray">
        <color rgba="0.1 0.1 0.1 1"/>
      </material>
    </visual>
    <collision name="right_top_pipe_collision">
      <origin rpy="0 1.5707963267948966 0" xyz="0.001 -0.156 0.1417"/>
      <geometry>
        <cylinder length="0.365" radius="0.0125"/>
      </geometry>
    </collision>
    <visual name="back_top_pipe_visual">
      <origin rpy="1.5707963267948966 0 0" xyz="-0.182 -0.0017 0.1413"/>
      <geometry>
        <cylinder length="0.3354" radius="0.0125"/>
      </geometry>
      <material name="dark_gray">
        <color rgba="0.1 0.1 0.1 1"/>
      </material>
    </visual>
    <collision name="back_top_pipe_collision">
      <origin rpy="1.5707963267948966 0 0" xyz="-0.182 -0.0017 0.1413"/>
      <geometry>
        <cylinder length="0.3354" radius="0.0125"/>
      </geometry>
    </collision>
    <visual name="front_top_pipe_visual">
      <origin rpy="1.5707963267948966 0 0" xyz="0.182 -0.0017 0.1413"/>
      <geometry>
        <cylinder length="0.3354" radius="0.0125"/>
      </geometry>
      <material name="dark_gray">
        <color rgba="0.1 0.1 0.1 1"/>
      </material>
    </visual>
    <collision name="front_top_pipe_collision">
      <origin rpy="1.5707963267948966 0 0" xyz="0.182 -0.0017 0.1413"/>
      <geometry>
        <cylinder length="0.3354" radius="0.0125"/>
      </geometry>
    </collision>
    <visual name="left_bottom_pipe_visual">
      <origin rpy="0 1.5707963267948966 0" xyz="0.001 0.156 -0.123"/>
      <geometry>
        <cylinder length="0.365" radius="0.0125"/>
      </geometry>
      <material name="dark_gray">
        <color rgba="0.1 0.1 0.1 1"/>
      </material>
    </visual>
    <collision name="left_bottom_pipe_collision">
      <origin rpy="0 1.5707963267948966 0" xyz="0.001 0.156 -0.123"/>
      <geometry>
        <cylinder length="0.365" radius="0.0125"/>
      </geometry>
    </collision>
    <visual name="right_bottom_pipe_visual">
      <origin rpy="0 1.5707963267948966 0" xyz="0.001 -0.156 -0.123"/>
      <geometry>
        <cylinder length="0.365" radius="0.0125"/>
      </geometry>
      <material name="dark_gray">
        <color rgba="0.1 0.1 0.1 1"/>
      </material>
    </visual>
    <collision name="right_bottom_pipe_collision">
      <origin rpy="0 1.5707963267948966 0" xyz="0.001 -0.156 -0.123"/>
      <geometry>
        <cylinder length="0.365" radius="0.0125"/>
      </geometry>
    </collision>
    <visual name="back_bottom_pipe_visual">
      <origin rpy="1.5707963267948966 0 0" xyz="-0.182 -0.0017 -0.123"/>
      <geometry>
        <cylinder length="0.3354" radius="0.0125"/>
      </geometry>
      <material name="dark_gray">
        <color rgba="0.1 0.1 0.1 1"/>
      </material>
    </visual>
    <collision name="back_bottom_pipe_collision">
      <origin rpy="1.5707963267948966 0 0" xyz="-0.182 -0.0017 -0.123"/>
      <geometry>
        <cylinder length="0.3354" radius="0.0125"/>
      </geometry>
    </collision>
    <visual name="front_bottom_pipe_visual">
      <origin rpy="1.5707963267948966 0 0" xyz="0.182 -0.0017 -0.123"/>
      <geometry>
        <cylinder length="0.3354" radius="0.0125"/>
      </geometry>
      <material name="dark_gray">
        <color rgba="0.1 0.1 0.1 1"/>
      </material>
    </visual>
    <collision name="front_bottom_pipe_collision">
      <origin rpy="1.5707963267948966 0 0" xyz="0.182 -0.0017 -0.123"/>
      <geometry>
        <cylinder length="0.3354" radius="0.0125"/>
      </geometry>
    </collision>
    <visual name="front_left_pipe_visual">
      <origin rpy="0 0 0" xyz="0.1857 -0.076 0.01"/>
      <geometry>
        <cylinder length="0.25" radius="0.0125"/>
      </geometry>
      <material name="dark_gray">
        <color rgba="0.1 0.1 0.1 1"/>
      </material>
    </visual>
    <collision name="front_left_pipe_collision">
      <origin rpy="0 0 0" xyz="0.1857 -0.076 0.01"/>
      <geometry>
        <cylinder length="0.25" radius="0.0125"/>
      </geometry>
    </collision>
    <visual name="front_right_pipe_visual">
      <origin rpy="0 0 0" xyz="0.1857 0.076 0.01"/>
      <geometry>
        <cylinder length="0.25" radius="0.0125"/>
      </geometry>
      <material name="dark_gray">
        <color rgba="0.1 0.1 0.1 1"/>
      </material>
    </visual>
    <collision name="front_right_pipe_collision">
      <origin rpy="0 0 0" xyz="0.1857 0.076 0.01"/>
      <geometry>
        <cylinder length="0.25" radius="0.0125"/>
      </geometry>
    </collision>
    <visual name="back_right_pipe_visual">
      <origin rpy="0 0 0" xyz="-0.1857 0.076 0.01"/>
      <geometry>
        <cylinder length="0.25" radius="0.0125"/>
      </geometry>
      <material name="dark_gray">
        <color rgba="0.1 0.1 0.1 1"/>
      </material>
    </visual>
    <collision name="back_right_pipe_collision">
      <origin rpy="0 0 0" xyz="-0.1857 0.076 0.01"/>
      <geometry>
        <cylinder length="0.25" radius="0.0125"/>
      </geometry>
    </collision>
    <visual name="back_left_pipe_visual">
      <origin rpy="0 0 0" xyz="-0.1857 -0.076 0.01"/>
      <geometry>
        <cylinder length="0.25" radius="0.0125"/>
      </geometry>
      <material name="dark_gray">
        <color rgba="0.1 0.1 0.1 1"/>
      </material>
    </visual>
    <collision name="back_left_pipe_collision">
      <origin rpy="0 0 0" xyz="-0.1857 -0.076 0.01"/>
      <geometry>
        <cylinder length="0.25" radius="0.0125"/>
      </geometry>
    </collision>
    <visual name="inner_front_left_pipe_visual">
      <origin rpy="0 0 0" xyz="0.1057 0.169 0.01"/>
      <geometry>
        <cylinder length="0.25" radius="0.0125"/>
      </geometry>
      <material name="dark_gray">
        <color rgba="0.1 0.1 0.1 1"/>
      </material>
    </visual>
    <collision name="inner_front_left_pipe_collision">
      <origin rpy="0 0 0" xyz="0.1057 0.169 0.01"/>
      <geometry>
        <cylinder length="0.25" radius="0.0125"/>
      </geometry>
    </collision>
    <visual name="inner_front_right_pipe_visual">
      <origin rpy="0 0 0" xyz="0.1057 -0.169 0.01"/>
      <geometry>
        <cylinder length="0.25" radius="0.0125"/>
      </geometry>
      <material name="dark_gray">
        <color rgba="0.1 0.1 0.1 1"/>
      </material>
    </visual>
    <collision name="inner_front_right_pipe_collision">
      <origin rpy="0 0 0" xyz="0.1057 -0.169 0.01"/>
      <geometry>
        <cylinder length="0.25" radius="0.0125"/>
      </geometry>
    </collision>
    <visual name="inner_back_left_pipe_visual">
      <origin rpy="0 0 0" xyz="-0.1057 0.169 0.01"/>
      <geometry>
        <cylinder length="0.25" radius="0.0125"/>
      </geometry>
      <material name="dark_gray">
        <color rgba="0.1 0.1 0.1 1"/>
      </material>
    </visual>
    <collision name="inner_back_left_pipe_collision">
      <origin rpy="0 0 0" xyz="-0.1057 0.169 0.01"/>
      <geometry>
        <cylinder length="0.25" radius="0.0125"/>
      </geometry>
    </collision>
    <visual name="inner_back_right_pipe_visual">
      <origin rpy="0 0 0" xyz="-0.1057 -0.169 0.01"/>
      <geometry>
        <cylinder length="0.25" radius="0.0125"/>
      </geometry>
      <material name="dark_gray">
        <color rgba="0.1 0.1 0.1 1"/>
      </material>
    </visual>
    <collision name="inner_back_right_pipe_collision">
      <origin rpy="0 0 0" xyz="-0.1057 -0.169 0.01"/>
      <geometry>
        <cylinder length="0.25" radius="0.0125"/>
      </geometry>
    </collision>
    <visual name="left_mid_back_horizontal_pipe_visual">
      <origin rpy="1.5707963267948966 0 0" xyz="-0.1058 0.114 0.0198"/>
      <geometry>
        <cylinder length="0.0702" radius="0.0125"/>
      </geometry>
      <material name="dark_gray">
        <color rgba="0.1 0.1 0.1 1"/>
      </material>
    </visual>
    <collision name="left_mid_back_horizontal_pipe_collision">
      <origin rpy="1.5707963267948966 0 0" xyz="-0.1058 0.114 0.0198"/>
      <geometry>
        <cylinder length="0.0702" radius="0.0125"/>
      </geometry>
    </collision>
    <visual name="left_mid_front_horizontal_pipe_visual">
      <origin rpy="1.5707963267948966 0 0" xyz="0.1058 0.114 0.0198"/>
      <geometry>
        <cylinder length="0.0702" radius="0.0125"/>
      </geometry>
      <material name="dark_gray">
        <color rgba="0.1 0.1 0.1 1"/>
      </material>
    </visual>
    <collision name="left_mid_front_horizontal_pipe_collision">
      <origin rpy="1.5707963267948966 0 0" xyz="0.1058 0.114 0.0198"/>
      <geometry>
        <cylinder length="0.0702" radius="0.0125"/>
      </geometry>
    </collision>
    <visual name="right_mid_front_horizontal_pipe_visual">
      <origin rpy="1.5707963267948966 0 0" xyz="0.1058 -0.114 0.0198"/>
      <geometry>
        <cylinder length="0.0702" radius="0.0125"/>
      </geometry>
      <material name="dark_gray">
        <color rgba="0.1 0.1 0.1 1"/>
      </material>
    </visual>
    <collision name="right_mid_front_horizontal_pipe_collision">
      <origin rpy="1.5707963267948966 0 0" xyz="0.1058 -0.114 0.0198"/>
      <geometry>
        <cylinder length="0.0702" radius="0.0125"/>
      </geometry>
    </collision>
    <visual name="right_mid_back_horizontal_pipe_visual">
      <origin rpy="1.5707963267948966 0 0" xyz="-0.1058 -0.114 0.0198"/>
      <geometry>
        <cylinder length="0.0702" radius="0.0125"/>
      </geometry>
      <material name="dark_gray">
        <color rgba="0.1 0.1 0.1 1"/>
      </material>
    </visual>
    <collision name="right_mid_back_horizontal_pipe_collision">
      <origin rpy="1.5707963267948966 0 0" xyz="-0.1058 -0.114 0.0198"/>
      <geometry>
        <cylinder length="0.0702" radius="0.0125"/>
      </geometry>
    </collision>
    <visual name="left_mid_long_pipe_visual">
      <origin rpy="0 1.5707963267948966 0" xyz="0.0007 0.0744 0.02"/>
      <geometry>
        <cylinder length="0.33" radius="0.0125"/>
      </geometry>
      <material name="dark_gray">
        <color rgba="0.1 0.1 0.1 1"/>
      </material>
    </visual>
    <collision name="left_mid_long_pipe_collision">
      <origin rpy="0 1.5707963267948966 0" xyz="0.0007 0.0744 0.02"/>
      <geometry>
        <cylinder length="0.33" radius="0.0125"/>
      </geometry>
    </collision>
    <visual name="right_mid_long_pipe_visual">
      <origin rpy="0 1.5707963267948966 0" xyz="0.0007 -0.0744 0.02"/>
      <geometry>
        <cylinder length="0.33" radius="0.0125"/>
      </geometry>
      <material name="dark_gray">
        <color rgba="0.1 0.1 0.1 1"/>
      </material>
    </visual>
    <collision name="right_mid_long_pipe_collision">
      <origin rpy="0 1.5707963267948966 0" xyz="0.0007 -0.0744 0.02"/>
      <geometry>
        <cylinder length="0.33" radius="0.0125"/>
      </geometry>
    </collision>
    <visual name="enclosure_visual">
      <origin rpy="0 1.5707963267948966 0" xyz="0.0007 -0.001 0.01"/>
      <geometry>
        <cylinder length="0.35" radius="0.055"/>
      </geometry>
      <material name="dark_gray">
        <color rgba="0.1 0.1 0.1 1"/>
      </material>
    </visual>
    <collision name="enclosure_collision">
      <origin rpy="0 1.5707963267948966 0" xyz="0.0007 -0.001 0.01"/>
      <geometry>
        <cylinder length="0.35" radius="0.055"/>
      </geometry>
    </collision>
  </link>
  <gazebo reference="base_link">
    <sensor name="imu_sensor" type="imu">
      <pose>0 0 0 3.141592653589793 0 0</pose>
      <always_on>1</always_on>
      <update_rate>400.0</update_rate>
    </sensor>
  </gazebo>
  <gazebo reference="base_link">
    <sensor name="vio_imu" type="imu">
      <pose>0 0 0 0 0 0</pose>
      <always_on>1</always_on>
      <update_rate>300.0</update_rate>
      <topic>/imu0</topic>
    </sensor>
  </gazebo>
  <link name="thruster1">
    <visual>
      <origin rpy="-1.571 0 0" xyz="0 0 0"/>
      <geometry>
        <mesh filename="model://bluerov2_heavy/meshes/t200_ccw_prop.dae"/>
      </geometry>
    </visual>
    <inertial>
      <mass value="0.002"/>
      <inertia ixx="0.001" ixy="0" ixz="0" iyy="0.001" iyz="0" izz="0.001"/>
    </inertial>
  </link>
  <joint name="thruster1_joint" type="continuous">
    <parent link="base_link"/>
    <child link="thruster1"/>
    <origin rpy="-1.571 1.571 -0.785" xyz="0.2201 -0.1126 -0.0224"/>
    <axis xyz="0 0 -1"/>
  </joint>
  <gazebo>
    <plugin filename="gz-sim-thruster-system" name="gz::sim::systems::Thruster">
      <namespace>prototype</namespace>
      <joint_name>thruster1_joint</joint_name>
      <thrust_coefficient>0.02</thrust_coefficient>
      <fluid_density>1000.0</fluid_density>
      <propeller_diameter>0.1</propeller_diameter>
      <velocity_control>true</velocity_control>
    </plugin>
  </gazebo>
  <link name="thruster2">
    <visual>
      <origin rpy="-1.571 0 0" xyz="0 0 0"/>
      <geometry>
        <mesh filename="model://bluerov2_heavy/meshes/t200_ccw_prop.dae"/>
      </geometry>
    </visual>
    <inertial>
      <mass value="0.002"/>
      <inertia ixx="0.001" ixy="0" ixz="0" iyy="0.001" iyz="0" izz="0.001"/>
    </inertial>
  </link>
  <joint name="thruster2_joint" type="continuous">
    <parent link="base_link"/>
    <child link="thruster2"/>
    <origin rpy="-1.571 1.571 -2.356" xyz="0.2201 0.1126 -0.0224"/>
    <axis xyz="0 0 -1"/>
  </joint>
  <gazebo>
    <plugin filename="gz-sim-thruster-system" name="gz::sim::systems::Thruster">
      <namespace>prototype</namespace>
      <joint_name>thruster2_joint</joint_name>
      <thrust_coefficient>0.02</thrust_coefficient>
      <fluid_density>1000.0</fluid_density>
      <propeller_diameter>0.1</propeller_diameter>
      <velocity_control>true</velocity_control>
    </plugin>
  </gazebo>
  <link name="thruster3">
    <visual>
      <origin rpy="-1.571 0 0" xyz="0 0 0"/>
      <geometry>
        <mesh filename="model://bluerov2_heavy/meshes/t200_cw_prop.dae"/>
      </geometry>
    </visual>
    <inertial>
      <mass value="0.002"/>
      <inertia ixx="0.001" ixy="0" ixz="0" iyy="0.001" iyz="0" izz="0.001"/>
    </inertial>
  </link>
  <joint name="thruster3_joint" type="continuous">
    <parent link="base_link"/>
    <child link="thruster3"/>
    <origin rpy="-1.571 1.571 0.785" xyz="-0.2201 -0.1126 -0.0224"/>
    <axis xyz="0 0 -1"/>
  </joint>
  <gazebo>
    <plugin filename="gz-sim-thruster-system" name="gz::sim::systems::Thruster">
      <namespace>prototype</namespace>
      <joint_name>thruster3_joint</joint_name>
      <thrust_coefficient>-0.02</thrust_coefficient>
      <fluid_density>1000.0</fluid_density>
      <propeller_diameter>0.1</propeller_diameter>
      <velocity_control>true</velocity_control>
    </plugin>
  </gazebo>
  <link name="thruster4">
    <visual>
      <origin rpy="-1.571 0 0" xyz="0 0 0"/>
      <geometry>
        <mesh filename="model://bluerov2_heavy/meshes/t200_cw_prop.dae"/>
      </geometry>
    </visual>
    <inertial>
      <mass value="0.002"/>
      <inertia ixx="0.001" ixy="0" ixz="0" iyy="0.001" iyz="0" izz="0.001"/>
    </inertial>
  </link>
  <joint name="thruster4_joint" type="continuous">
    <parent link="base_link"/>
    <child link="thruster4"/>
    <origin rpy="-1.571 1.571 0.785" xyz="-0.2201 0.1126 -0.0224"/>
    <axis xyz="0 0 -1"/>
  </joint>
  <gazebo>
    <plugin filename="gz-sim-thruster-system" name="gz::sim::systems::Thruster">
      <namespace>prototype</namespace>
      <joint_name>thruster4_joint</joint_name>
      <thrust_coefficient>-0.02</thrust_coefficient>
      <fluid_density>1000.0</fluid_density>
      <propeller_diameter>0.1</propeller_diameter>
      <velocity_control>true</velocity_control>
    </plugin>
  </gazebo>
  <link name="thruster5">
    <visual>
      <origin rpy="-1.571 0 0" xyz="0 0 0"/>
      <geometry>
        <mesh filename="model://bluerov2_heavy/meshes/t200_ccw_prop.dae"/>
      </geometry>
    </visual>
    <inertial>
      <mass value="0.002"/>
      <inertia ixx="0.001" ixy="0" ixz="0" iyy="0.001" iyz="0" izz="0.001"/>
    </inertial>
  </link>
  <joint name="thruster5_joint" type="continuous">
    <parent link="base_link"/>
    <child link="thruster5"/>
    <origin rpy="0 0 0" xyz="0.0884 -0.2126 0.0056"/>
    <axis xyz="0 0 -1"/>
  </joint>
  <gazebo>
    <plugin filename="gz-sim-thruster-system" name="gz::sim::systems::Thruster">
      <namespace>prototype</namespace>
      <joint_name>thruster5_joint</joint_name>
      <thrust_coefficient>0.02</thrust_coefficient>
      <fluid_density>1000.0</fluid_density>
      <propeller_diameter>0.1</propeller_diameter>
      <velocity_control>true</velocity_control>
    </plugin>
  </gazebo>
  <link name="thruster6">
    <visual>
      <origin rpy="-1.571 0 0" xyz="0 0 0"/>
      <geometry>
        <mesh filename="model://bluerov2_heavy/meshes/t200_cw_prop.dae"/>
      </geometry>
    </visual>
    <inertial>
      <mass value="0.002"/>
      <inertia ixx="0.001" ixy="0" ixz="0" iyy="0.001" iyz="0" izz="0.001"/>
    </inertial>
  </link>
  <joint name="thruster6_joint" type="continuous">
    <parent link="base_link"/>
    <child link="thruster6"/>
    <origin rpy="0 0 0" xyz="0.0884 0.2126 0.0056"/>
    <axis xyz="0 0 -1"/>
  </joint>
  <gazebo>
    <plugin filename="gz-sim-thruster-system" name="gz::sim::systems::Thruster">
      <namespace>prototype</namespace>
      <joint_name>thruster6_joint</joint_name>
      <thrust_coefficient>-0.02</thrust_coefficient>
      <fluid_density>1000.0</fluid_density>
      <propeller_diameter>0.1</propeller_diameter>
      <velocity_control>true</velocity_control>
    </plugin>
  </gazebo>
  <link name="thruster7">
    <visual>
      <origin rpy="-1.571 0 0" xyz="0 0 0"/>
      <geometry>
        <mesh filename="model://bluerov2_heavy/meshes/t200_cw_prop.dae"/>
      </geometry>
    </visual>
    <inertial>
      <mass value="0.002"/>
      <inertia ixx="0.001" ixy="0" ixz="0" iyy="0.001" iyz="0" izz="0.001"/>
    </inertial>
  </link>
  <joint name="thruster7_joint" type="continuous">
    <parent link="base_link"/>
    <child link="thruster7"/>
    <origin rpy="0 0 0" xyz="-0.0884 -0.2126 0.0056"/>
    <axis xyz="0 0 -1"/>
  </joint>
  <gazebo>
    <plugin filename="gz-sim-thruster-system" name="gz::sim::systems::Thruster">
      <namespace>prototype</namespace>
      <joint_name>thruster7_joint</joint_name>
      <thrust_coefficient>-0.02</thrust_coefficient>
      <fluid_density>1000.0</fluid_density>
      <propeller_diameter>0.1</propeller_diameter>
      <velocity_control>true</velocity_control>
    </plugin>
  </gazebo>
  <link name="thruster8">
    <visual>
      <origin rpy="-1.571 0 0" xyz="0 0 0"/>
      <geometry>
        <mesh filename="model://bluerov2_heavy/meshes/t200_ccw_prop.dae"/>
      </geometry>
    </visual>
    <inertial>
      <mass value="0.002"/>
      <inertia ixx="0.001" ixy="0" ixz="0" iyy="0.001" iyz="0" izz="0.001"/>
    </inertial>
  </link>
  <joint name="thruster8_joint" type="continuous">
    <parent link="base_link"/>
    <child link="thruster8"/>
    <origin rpy="0 0 0" xyz="-0.0884 0.2126 0.0056"/>
    <axis xyz="0 0 -1"/>
  </joint>
  <gazebo>
    <plugin filename="gz-sim-thruster-system" name="gz::sim::systems::Thruster">
      <namespace>prototype</namespace>
      <joint_name>thruster8_joint</joint_name>
      <thrust_coefficient>0.02</thrust_coefficient>
      <fluid_density>1000.0</fluid_density>
      <propeller_diameter>0.1</propeller_diameter>
      <velocity_control>true</velocity_control>
    </plugin>
  </gazebo>
</robot>
